[2021-01-29 04:48:08,677 | CRITICAL | /home/joakim/miniconda/envs/pyfunceble4/lib/python3.9/site-packages/PyFunceble/cli/system/launcher.py:858@start | TPID140578035738432:MainThread | PPID1538458:MainProcess]:
Fatal error.
Traceback (most recent call last):
  File "/home/joakim/.local/lib/python3.9/site-packages/sqlalchemy/engine/base.py", line 2336, in _wrap_pool_connect
    return fn()
  File "/home/joakim/.local/lib/python3.9/site-packages/sqlalchemy/pool/base.py", line 364, in connect
    return _ConnectionFairy._checkout(self)
  File "/home/joakim/.local/lib/python3.9/site-packages/sqlalchemy/pool/base.py", line 778, in _checkout
    fairy = _ConnectionRecord.checkout(pool)
  File "/home/joakim/.local/lib/python3.9/site-packages/sqlalchemy/pool/base.py", line 495, in checkout
    rec = pool._do_get()
  File "/home/joakim/.local/lib/python3.9/site-packages/sqlalchemy/pool/impl.py", line 241, in _do_get
    return self._create_connection()
  File "/home/joakim/.local/lib/python3.9/site-packages/sqlalchemy/pool/base.py", line 309, in _create_connection
    return _ConnectionRecord(self)
  File "/home/joakim/.local/lib/python3.9/site-packages/sqlalchemy/pool/base.py", line 440, in __init__
    self.__connect(first_connect_check=True)
  File "/home/joakim/.local/lib/python3.9/site-packages/sqlalchemy/pool/base.py", line 661, in __connect
    pool.logger.debug("Error on connect(): %s", e)
  File "/home/joakim/.local/lib/python3.9/site-packages/sqlalchemy/util/langhelpers.py", line 68, in __exit__
    compat.raise_(
  File "/home/joakim/.local/lib/python3.9/site-packages/sqlalchemy/util/compat.py", line 182, in raise_
    raise exception
  File "/home/joakim/.local/lib/python3.9/site-packages/sqlalchemy/pool/base.py", line 656, in __connect
    connection = pool._invoke_creator(self)
  File "/home/joakim/.local/lib/python3.9/site-packages/sqlalchemy/engine/strategies.py", line 114, in connect
    return dialect.connect(*cargs, **cparams)
  File "/home/joakim/.local/lib/python3.9/site-packages/sqlalchemy/engine/default.py", line 493, in connect
    return self.dbapi.connect(*cargs, **cparams)
  File "/home/joakim/.local/lib/python3.9/site-packages/pymysql/__init__.py", line 94, in Connect
    return Connection(*args, **kwargs)
  File "/home/joakim/.local/lib/python3.9/site-packages/pymysql/connections.py", line 327, in __init__
    self.connect()
  File "/home/joakim/.local/lib/python3.9/site-packages/pymysql/connections.py", line 588, in connect
    self._request_authentication()
  File "/home/joakim/.local/lib/python3.9/site-packages/pymysql/connections.py", line 853, in _request_authentication
    auth_packet = self._read_packet()
  File "/home/joakim/.local/lib/python3.9/site-packages/pymysql/connections.py", line 676, in _read_packet
    packet.raise_for_error()
  File "/home/joakim/.local/lib/python3.9/site-packages/pymysql/protocol.py", line 223, in raise_for_error
    err.raise_mysql_exception(self._data)
  File "/home/joakim/.local/lib/python3.9/site-packages/pymysql/err.py", line 107, in raise_mysql_exception
    raise errorclass(errno, errval)
pymysql.err.OperationalError: (1045, "Access denied for user 'pyfunceble'@'127.0.0.1' (using password: YES)")

The above exception was the direct cause of the following exception:

Traceback (most recent call last):
  File "/home/joakim/miniconda/envs/pyfunceble4/lib/python3.9/site-packages/PyFunceble/cli/system/launcher.py", line 832, in start
    self.migrator_process_manager.start()
  File "/home/joakim/miniconda/envs/pyfunceble4/lib/python3.9/site-packages/PyFunceble/cli/processes/migrator.py", line 313, in start
    Alembic().upgrade()
  File "/home/joakim/miniconda/envs/pyfunceble4/lib/python3.9/site-packages/PyFunceble/cli/migrators/alembic.py", line 92, in wrapper
    return func(self, *args, **kwargs)  # pylint: disable=not-callable
  File "/home/joakim/miniconda/envs/pyfunceble4/lib/python3.9/site-packages/PyFunceble/cli/migrators/alembic.py", line 170, in upgrade
    if not MariaDBMigratorBase.does_table_exists(
  File "/home/joakim/miniconda/envs/pyfunceble4/lib/python3.9/site-packages/PyFunceble/cli/migrators/mariadb/base.py", line 98, in does_table_exists
    result = db_session.execute(
  File "/home/joakim/.local/lib/python3.9/site-packages/sqlalchemy/orm/session.py", line 1291, in execute
    return self._connection_for_bind(bind, close_with_result=True).execute(
  File "/home/joakim/.local/lib/python3.9/site-packages/sqlalchemy/orm/session.py", line 1146, in _connection_for_bind
    return self.transaction._connection_for_bind(
  File "/home/joakim/.local/lib/python3.9/site-packages/sqlalchemy/orm/session.py", line 433, in _connection_for_bind
    conn = bind._contextual_connect()
  File "/home/joakim/.local/lib/python3.9/site-packages/sqlalchemy/engine/base.py", line 2302, in _contextual_connect
    self._wrap_pool_connect(self.pool.connect, None),
  File "/home/joakim/.local/lib/python3.9/site-packages/sqlalchemy/engine/base.py", line 2339, in _wrap_pool_connect
    Connection._handle_dbapi_exception_noconnection(
  File "/home/joakim/.local/lib/python3.9/site-packages/sqlalchemy/engine/base.py", line 1583, in _handle_dbapi_exception_noconnection
    util.raise_(
  File "/home/joakim/.local/lib/python3.9/site-packages/sqlalchemy/util/compat.py", line 182, in raise_
    raise exception
  File "/home/joakim/.local/lib/python3.9/site-packages/sqlalchemy/engine/base.py", line 2336, in _wrap_pool_connect
    return fn()
  File "/home/joakim/.local/lib/python3.9/site-packages/sqlalchemy/pool/base.py", line 364, in connect
    return _ConnectionFairy._checkout(self)
  File "/home/joakim/.local/lib/python3.9/site-packages/sqlalchemy/pool/base.py", line 778, in _checkout
    fairy = _ConnectionRecord.checkout(pool)
  File "/home/joakim/.local/lib/python3.9/site-packages/sqlalchemy/pool/base.py", line 495, in checkout
    rec = pool._do_get()
  File "/home/joakim/.local/lib/python3.9/site-packages/sqlalchemy/pool/impl.py", line 241, in _do_get
    return self._create_connection()
  File "/home/joakim/.local/lib/python3.9/site-packages/sqlalchemy/pool/base.py", line 309, in _create_connection
    return _ConnectionRecord(self)
  File "/home/joakim/.local/lib/python3.9/site-packages/sqlalchemy/pool/base.py", line 440, in __init__
    self.__connect(first_connect_check=True)
  File "/home/joakim/.local/lib/python3.9/site-packages/sqlalchemy/pool/base.py", line 661, in __connect
    pool.logger.debug("Error on connect(): %s", e)
  File "/home/joakim/.local/lib/python3.9/site-packages/sqlalchemy/util/langhelpers.py", line 68, in __exit__
    compat.raise_(
  File "/home/joakim/.local/lib/python3.9/site-packages/sqlalchemy/util/compat.py", line 182, in raise_
    raise exception
  File "/home/joakim/.local/lib/python3.9/site-packages/sqlalchemy/pool/base.py", line 656, in __connect
    connection = pool._invoke_creator(self)
  File "/home/joakim/.local/lib/python3.9/site-packages/sqlalchemy/engine/strategies.py", line 114, in connect
    return dialect.connect(*cargs, **cparams)
  File "/home/joakim/.local/lib/python3.9/site-packages/sqlalchemy/engine/default.py", line 493, in connect
    return self.dbapi.connect(*cargs, **cparams)
  File "/home/joakim/.local/lib/python3.9/site-packages/pymysql/__init__.py", line 94, in Connect
    return Connection(*args, **kwargs)
  File "/home/joakim/.local/lib/python3.9/site-packages/pymysql/connections.py", line 327, in __init__
    self.connect()
  File "/home/joakim/.local/lib/python3.9/site-packages/pymysql/connections.py", line 588, in connect
    self._request_authentication()
  File "/home/joakim/.local/lib/python3.9/site-packages/pymysql/connections.py", line 853, in _request_authentication
    auth_packet = self._read_packet()
  File "/home/joakim/.local/lib/python3.9/site-packages/pymysql/connections.py", line 676, in _read_packet
    packet.raise_for_error()
  File "/home/joakim/.local/lib/python3.9/site-packages/pymysql/protocol.py", line 223, in raise_for_error
    err.raise_mysql_exception(self._data)
  File "/home/joakim/.local/lib/python3.9/site-packages/pymysql/err.py", line 107, in raise_mysql_exception
    raise errorclass(errno, errval)
sqlalchemy.exc.OperationalError: (pymysql.err.OperationalError) (1045, "Access denied for user 'pyfunceble'@'127.0.0.1' (using password: YES)")
(Background on this error at: http://sqlalche.me/e/13/e3q8)
[2021-01-29 11:58:03,182 | CRITICAL | /home/joakim/miniconda/envs/pyfunceble4/lib/python3.9/site-packages/PyFunceble/cli/system/launcher.py:858@start | TPID139713844442944:MainThread | PPID1542819:MainProcess]:
Fatal error.
Traceback (most recent call last):
  File "/home/joakim/.local/lib/python3.9/site-packages/sqlalchemy/engine/base.py", line 2336, in _wrap_pool_connect
    return fn()
  File "/home/joakim/.local/lib/python3.9/site-packages/sqlalchemy/pool/base.py", line 364, in connect
    return _ConnectionFairy._checkout(self)
  File "/home/joakim/.local/lib/python3.9/site-packages/sqlalchemy/pool/base.py", line 778, in _checkout
    fairy = _ConnectionRecord.checkout(pool)
  File "/home/joakim/.local/lib/python3.9/site-packages/sqlalchemy/pool/base.py", line 495, in checkout
    rec = pool._do_get()
  File "/home/joakim/.local/lib/python3.9/site-packages/sqlalchemy/pool/impl.py", line 241, in _do_get
    return self._create_connection()
  File "/home/joakim/.local/lib/python3.9/site-packages/sqlalchemy/pool/base.py", line 309, in _create_connection
    return _ConnectionRecord(self)
  File "/home/joakim/.local/lib/python3.9/site-packages/sqlalchemy/pool/base.py", line 440, in __init__
    self.__connect(first_connect_check=True)
  File "/home/joakim/.local/lib/python3.9/site-packages/sqlalchemy/pool/base.py", line 661, in __connect
    pool.logger.debug("Error on connect(): %s", e)
  File "/home/joakim/.local/lib/python3.9/site-packages/sqlalchemy/util/langhelpers.py", line 68, in __exit__
    compat.raise_(
  File "/home/joakim/.local/lib/python3.9/site-packages/sqlalchemy/util/compat.py", line 182, in raise_
    raise exception
  File "/home/joakim/.local/lib/python3.9/site-packages/sqlalchemy/pool/base.py", line 656, in __connect
    connection = pool._invoke_creator(self)
  File "/home/joakim/.local/lib/python3.9/site-packages/sqlalchemy/engine/strategies.py", line 114, in connect
    return dialect.connect(*cargs, **cparams)
  File "/home/joakim/.local/lib/python3.9/site-packages/sqlalchemy/engine/default.py", line 493, in connect
    return self.dbapi.connect(*cargs, **cparams)
  File "/home/joakim/.local/lib/python3.9/site-packages/pymysql/__init__.py", line 94, in Connect
    return Connection(*args, **kwargs)
  File "/home/joakim/.local/lib/python3.9/site-packages/pymysql/connections.py", line 327, in __init__
    self.connect()
  File "/home/joakim/.local/lib/python3.9/site-packages/pymysql/connections.py", line 588, in connect
    self._request_authentication()
  File "/home/joakim/.local/lib/python3.9/site-packages/pymysql/connections.py", line 853, in _request_authentication
    auth_packet = self._read_packet()
  File "/home/joakim/.local/lib/python3.9/site-packages/pymysql/connections.py", line 676, in _read_packet
    packet.raise_for_error()
  File "/home/joakim/.local/lib/python3.9/site-packages/pymysql/protocol.py", line 223, in raise_for_error
    err.raise_mysql_exception(self._data)
  File "/home/joakim/.local/lib/python3.9/site-packages/pymysql/err.py", line 107, in raise_mysql_exception
    raise errorclass(errno, errval)
pymysql.err.OperationalError: (1045, "Access denied for user 'pyfunceble'@'127.0.0.1' (using password: YES)")

The above exception was the direct cause of the following exception:

Traceback (most recent call last):
  File "/home/joakim/miniconda/envs/pyfunceble4/lib/python3.9/site-packages/PyFunceble/cli/system/launcher.py", line 832, in start
    self.migrator_process_manager.start()
  File "/home/joakim/miniconda/envs/pyfunceble4/lib/python3.9/site-packages/PyFunceble/cli/processes/migrator.py", line 313, in start
    Alembic().upgrade()
  File "/home/joakim/miniconda/envs/pyfunceble4/lib/python3.9/site-packages/PyFunceble/cli/migrators/alembic.py", line 92, in wrapper
    return func(self, *args, **kwargs)  # pylint: disable=not-callable
  File "/home/joakim/miniconda/envs/pyfunceble4/lib/python3.9/site-packages/PyFunceble/cli/migrators/alembic.py", line 170, in upgrade
    if not MariaDBMigratorBase.does_table_exists(
  File "/home/joakim/miniconda/envs/pyfunceble4/lib/python3.9/site-packages/PyFunceble/cli/migrators/mariadb/base.py", line 98, in does_table_exists
    result = db_session.execute(
  File "/home/joakim/.local/lib/python3.9/site-packages/sqlalchemy/orm/session.py", line 1291, in execute
    return self._connection_for_bind(bind, close_with_result=True).execute(
  File "/home/joakim/.local/lib/python3.9/site-packages/sqlalchemy/orm/session.py", line 1146, in _connection_for_bind
    return self.transaction._connection_for_bind(
  File "/home/joakim/.local/lib/python3.9/site-packages/sqlalchemy/orm/session.py", line 433, in _connection_for_bind
    conn = bind._contextual_connect()
  File "/home/joakim/.local/lib/python3.9/site-packages/sqlalchemy/engine/base.py", line 2302, in _contextual_connect
    self._wrap_pool_connect(self.pool.connect, None),
  File "/home/joakim/.local/lib/python3.9/site-packages/sqlalchemy/engine/base.py", line 2339, in _wrap_pool_connect
    Connection._handle_dbapi_exception_noconnection(
  File "/home/joakim/.local/lib/python3.9/site-packages/sqlalchemy/engine/base.py", line 1583, in _handle_dbapi_exception_noconnection
    util.raise_(
  File "/home/joakim/.local/lib/python3.9/site-packages/sqlalchemy/util/compat.py", line 182, in raise_
    raise exception
  File "/home/joakim/.local/lib/python3.9/site-packages/sqlalchemy/engine/base.py", line 2336, in _wrap_pool_connect
    return fn()
  File "/home/joakim/.local/lib/python3.9/site-packages/sqlalchemy/pool/base.py", line 364, in connect
    return _ConnectionFairy._checkout(self)
  File "/home/joakim/.local/lib/python3.9/site-packages/sqlalchemy/pool/base.py", line 778, in _checkout
    fairy = _ConnectionRecord.checkout(pool)
  File "/home/joakim/.local/lib/python3.9/site-packages/sqlalchemy/pool/base.py", line 495, in checkout
    rec = pool._do_get()
  File "/home/joakim/.local/lib/python3.9/site-packages/sqlalchemy/pool/impl.py", line 241, in _do_get
    return self._create_connection()
  File "/home/joakim/.local/lib/python3.9/site-packages/sqlalchemy/pool/base.py", line 309, in _create_connection
    return _ConnectionRecord(self)
  File "/home/joakim/.local/lib/python3.9/site-packages/sqlalchemy/pool/base.py", line 440, in __init__
    self.__connect(first_connect_check=True)
  File "/home/joakim/.local/lib/python3.9/site-packages/sqlalchemy/pool/base.py", line 661, in __connect
    pool.logger.debug("Error on connect(): %s", e)
  File "/home/joakim/.local/lib/python3.9/site-packages/sqlalchemy/util/langhelpers.py", line 68, in __exit__
    compat.raise_(
  File "/home/joakim/.local/lib/python3.9/site-packages/sqlalchemy/util/compat.py", line 182, in raise_
    raise exception
  File "/home/joakim/.local/lib/python3.9/site-packages/sqlalchemy/pool/base.py", line 656, in __connect
    connection = pool._invoke_creator(self)
  File "/home/joakim/.local/lib/python3.9/site-packages/sqlalchemy/engine/strategies.py", line 114, in connect
    return dialect.connect(*cargs, **cparams)
  File "/home/joakim/.local/lib/python3.9/site-packages/sqlalchemy/engine/default.py", line 493, in connect
    return self.dbapi.connect(*cargs, **cparams)
  File "/home/joakim/.local/lib/python3.9/site-packages/pymysql/__init__.py", line 94, in Connect
    return Connection(*args, **kwargs)
  File "/home/joakim/.local/lib/python3.9/site-packages/pymysql/connections.py", line 327, in __init__
    self.connect()
  File "/home/joakim/.local/lib/python3.9/site-packages/pymysql/connections.py", line 588, in connect
    self._request_authentication()
  File "/home/joakim/.local/lib/python3.9/site-packages/pymysql/connections.py", line 853, in _request_authentication
    auth_packet = self._read_packet()
  File "/home/joakim/.local/lib/python3.9/site-packages/pymysql/connections.py", line 676, in _read_packet
    packet.raise_for_error()
  File "/home/joakim/.local/lib/python3.9/site-packages/pymysql/protocol.py", line 223, in raise_for_error
    err.raise_mysql_exception(self._data)
  File "/home/joakim/.local/lib/python3.9/site-packages/pymysql/err.py", line 107, in raise_mysql_exception
    raise errorclass(errno, errval)
sqlalchemy.exc.OperationalError: (pymysql.err.OperationalError) (1045, "Access denied for user 'pyfunceble'@'127.0.0.1' (using password: YES)")
(Background on this error at: http://sqlalche.me/e/13/e3q8)
